2024-05-16 00:29:07,536 INFO    StreamThr :76603 [internal.py:wandb_internal():85] W&B internal server running at pid: 76603, started at: 2024-05-16 00:29:07.535541
2024-05-16 00:29:07,538 DEBUG   HandlerThread:76603 [handler.py:handle_request():158] handle_request: status
2024-05-16 00:29:07,540 INFO    WriterThread:76603 [datastore.py:open_for_write():87] open: /Users/binliu/Documents/small_nice/wandb/wandb_proj/wandb/run-20240516_002907-5fowbh69/run-5fowbh69.wandb
2024-05-16 00:29:07,541 DEBUG   SenderThread:76603 [sender.py:send():378] send: header
2024-05-16 00:29:07,563 DEBUG   SenderThread:76603 [sender.py:send():378] send: run
2024-05-16 00:29:07,735 ERROR   SenderThread:76603 [internal_api.py:execute():344] 401 response executing GraphQL.
2024-05-16 00:29:07,735 ERROR   SenderThread:76603 [internal_api.py:execute():345] {"errors":[{"message":"user is not logged in","path":["upsertBucket"],"extensions":{"code":"PERMISSION_ERROR"}}],"data":{"upsertBucket":null}}
2024-05-16 00:29:07,735 ERROR   SenderThread:76603 [sender.py:send_run():970] The API key you provided is either invalid or missing.  If the `WANDB_API_KEY` environment variable is set, make sure it is correct. Otherwise, to resolve this issue, you may try running the 'wandb login --relogin' command. If you are using a local server, make sure that you're using the correct hostname. If you're not sure, you can try logging in again using the 'wandb login --relogin --host [hostname]' command.(Error 401: Unauthorized)
Traceback (most recent call last):
  File "/Users/binliu/.pyenv/versions/3.12.2/lib/python3.12/site-packages/wandb/sdk/lib/retry.py", line 131, in __call__
    result = self._call_fn(*args, **kwargs)
             ^^^^^^^^^^^^^^^^^^^^^^^^^^^^^^
  File "/Users/binliu/.pyenv/versions/3.12.2/lib/python3.12/site-packages/wandb/sdk/internal/internal_api.py", line 340, in execute
    return self.client.execute(*args, **kwargs)  # type: ignore
           ^^^^^^^^^^^^^^^^^^^^^^^^^^^^^^^^^^^^
  File "/Users/binliu/.pyenv/versions/3.12.2/lib/python3.12/site-packages/wandb/vendor/gql-0.2.0/wandb_gql/client.py", line 52, in execute
    result = self._get_result(document, *args, **kwargs)
             ^^^^^^^^^^^^^^^^^^^^^^^^^^^^^^^^^^^^^^^^^^^
  File "/Users/binliu/.pyenv/versions/3.12.2/lib/python3.12/site-packages/wandb/vendor/gql-0.2.0/wandb_gql/client.py", line 60, in _get_result
    return self.transport.execute(document, *args, **kwargs)
           ^^^^^^^^^^^^^^^^^^^^^^^^^^^^^^^^^^^^^^^^^^^^^^^^^
  File "/Users/binliu/.pyenv/versions/3.12.2/lib/python3.12/site-packages/wandb/sdk/lib/gql_request.py", line 59, in execute
    request.raise_for_status()
  File "/Users/binliu/.pyenv/versions/3.12.2/lib/python3.12/site-packages/requests/models.py", line 1021, in raise_for_status
    raise HTTPError(http_error_msg, response=self)
requests.exceptions.HTTPError: 401 Client Error: Unauthorized for url: https://api.wandb.ai/graphql

During handling of the above exception, another exception occurred:

Traceback (most recent call last):
  File "/Users/binliu/.pyenv/versions/3.12.2/lib/python3.12/site-packages/wandb/sdk/internal/sender.py", line 968, in send_run
    server_run = self._init_run(run, config_value_dict)
                 ^^^^^^^^^^^^^^^^^^^^^^^^^^^^^^^^^^^^^^
  File "/Users/binliu/.pyenv/versions/3.12.2/lib/python3.12/site-packages/wandb/sdk/internal/sender.py", line 1013, in _init_run
    server_run, inserted, server_messages = self._api.upsert_run(
                                            ^^^^^^^^^^^^^^^^^^^^^
  File "/Users/binliu/.pyenv/versions/3.12.2/lib/python3.12/site-packages/wandb/apis/normalize.py", line 73, in wrapper
    raise err
  File "/Users/binliu/.pyenv/versions/3.12.2/lib/python3.12/site-packages/wandb/apis/normalize.py", line 41, in wrapper
    return func(*args, **kwargs)
           ^^^^^^^^^^^^^^^^^^^^^
  File "/Users/binliu/.pyenv/versions/3.12.2/lib/python3.12/site-packages/wandb/sdk/internal/internal_api.py", line 2188, in upsert_run
    response = self.gql(
               ^^^^^^^^^
  File "/Users/binliu/.pyenv/versions/3.12.2/lib/python3.12/site-packages/wandb/sdk/internal/internal_api.py", line 312, in gql
    ret = self._retry_gql(
          ^^^^^^^^^^^^^^^^
  File "/Users/binliu/.pyenv/versions/3.12.2/lib/python3.12/site-packages/wandb/sdk/lib/retry.py", line 147, in __call__
    retry_timedelta_triggered = check_retry_fn(e)
                                ^^^^^^^^^^^^^^^^^
  File "/Users/binliu/.pyenv/versions/3.12.2/lib/python3.12/site-packages/wandb/util.py", line 965, in check_retry_fn
    return fallback_retry_fn(e)
           ^^^^^^^^^^^^^^^^^^^^
  File "/Users/binliu/.pyenv/versions/3.12.2/lib/python3.12/site-packages/wandb/util.py", line 896, in no_retry_auth
    raise AuthenticationError(
wandb.errors.AuthenticationError: The API key you provided is either invalid or missing.  If the `WANDB_API_KEY` environment variable is set, make sure it is correct. Otherwise, to resolve this issue, you may try running the 'wandb login --relogin' command. If you are using a local server, make sure that you're using the correct hostname. If you're not sure, you can try logging in again using the 'wandb login --relogin --host [hostname]' command.(Error 401: Unauthorized)
2024-05-16 00:29:08,150 DEBUG   HandlerThread:76603 [handler.py:handle_request():158] handle_request: shutdown
2024-05-16 00:29:08,150 INFO    HandlerThread:76603 [handler.py:finish():882] shutting down handler
2024-05-16 00:29:08,563 INFO    WriterThread:76603 [datastore.py:close():296] close: /Users/binliu/Documents/small_nice/wandb/wandb_proj/wandb/run-20240516_002907-5fowbh69/run-5fowbh69.wandb
2024-05-16 00:29:08,761 INFO    SenderThread:76603 [sender.py:finish():1545] shutting down sender
